<sdf version='1.6'>
  <model name='jebediah'>
    <link name='base_link'>
      <pose frame=''>0 0 0 0 -0 0</pose>
      <inertial>
        <pose frame=''>0 0 0 0 -0 0</pose>
        <mass>0.297355</mass>
        <inertia>
          <ixx>0.00102328</ixx>
          <ixy>-1.09233e-06</ixy>
          <ixz>-1.70446e-05</ixz>
          <iyy>0.00112582</iyy>
          <iyz>-2.26629e-07</iyz>
          <izz>0.00147666</izz>
        </inertia>
      </inertial>
      <collision name='base_link_collision'>
        <pose frame=''>0 0 0 0 -0 0</pose>
        <geometry>
          <mesh>
            <scale>1 1 1</scale>
            <uri>model://jebediah/meshes/base_link.STL</uri>
          </mesh>
        </geometry>
      </collision>
      <visual name='base_link_visual'>
        <pose frame=''>0 0 0 0 -0 0</pose>
        <geometry>
          <mesh>
            <scale>1 1 1</scale>
            <uri>model://jebediah/meshes/base_link.STL</uri>
          </mesh>
        </geometry>
      </visual>
    </link>
    <link name='Coxa_4'>
      <pose frame=''>-0.075112 -0.069996 -0.034543 0 0 -2.3554</pose>
      <inertial>
        <pose frame=''>0.01481 -2.2e-05 0.029381 0 -0 0</pose>
        <mass>0.124104</mass>
        <inertia>
          <ixx>8.18267e-05</ixx>
          <ixy>-1.14318e-08</ixy>
          <ixz>6.1428e-07</ixz>
          <iyy>7.27029e-05</iyy>
          <iyz>2.00528e-08</iyz>
          <izz>0.000120694</izz>
        </inertia>
      </inertial>
      <collision name='Coxa_4_collision'>
        <pose frame=''>0 0 0 0 -0 0</pose>
        <geometry>
          <mesh>
            <scale>1 1 1</scale>
            <uri>model://jebediah/meshes/Coxa_4.STL</uri>
          </mesh>
        </geometry>
      </collision>
      <visual name='Coxa_4_visual'>
        <pose frame=''>0 0 0 0 -0 0</pose>
        <geometry>
          <mesh>
            <scale>1 1 1</scale>
            <uri>model://jebediah/meshes/Coxa_4.STL</uri>
          </mesh>
        </geometry>
      </visual>
    </link>
    <joint name='Serv_Coxa_4' type='revolute'>
      <child>Coxa_4</child>
      <parent>base_link</parent>
      <axis>
        <xyz>-0 -0 1</xyz>
        <limit>
          <lower>-1.4</lower>
          <upper>1.4</upper>
          <effort>0.9</effort>
          <velocity>5</velocity>
        </limit>
        <dynamics>
          <spring_reference>0</spring_reference>
          <spring_stiffness>0</spring_stiffness>
        </dynamics>
        <use_parent_model_frame>1</use_parent_model_frame>
      </axis>
    </joint>
    <link name='Femur_4'>
      <pose frame=''>-0.140912 -0.095678 -0.005543 0 0 -2.3554</pose>
      <inertial>
        <pose frame=''>0.051468 0.026889 1.6e-05 0 -0 0</pose>
        <mass>0.158176</mass>
        <inertia>
          <ixx>8.72873e-05</ixx>
          <ixy>1.35179e-10</ixy>
          <ixz>-6.32899e-12</ixz>
          <iyy>0.000251934</iyy>
          <iyz>-3.84978e-08</iyz>
          <izz>0.000324907</izz>
        </inertia>
      </inertial>
      <collision name='Femur_4_collision'>
        <pose frame=''>0 0 0 0 -0 0</pose>
        <geometry>
          <mesh>
            <scale>1 1 1</scale>
            <uri>model://jebediah/meshes/Femur_4.STL</uri>
          </mesh>
        </geometry>
      </collision>
      <visual name='Femur_4_visual'>
        <pose frame=''>0 0 0 0 -0 0</pose>
        <geometry>
          <mesh>
            <scale>1 1 1</scale>
            <uri>model://jebediah/meshes/Femur_4.STL</uri>
          </mesh>
        </geometry>
      </visual>
    </link>
    <joint name='Servo_Femur_4_1' type='revolute'>
      <child>Femur_4</child>
      <parent>Coxa_4</parent>
      <axis>
        <xyz>0.707668 -0.706545 0</xyz>
        <limit>
          <lower>-1.4</lower>
          <upper>1.4</upper>
          <effort>0.9</effort>
          <velocity>5</velocity>
        </limit>
        <dynamics>
          <spring_reference>0</spring_reference>
          <spring_stiffness>0</spring_stiffness>
        </dynamics>
        <use_parent_model_frame>1</use_parent_model_frame>
      </axis>
    </joint>
    <link name='Tibia_4'>
      <pose frame=''>-0.193532 -0.188605 -0.005543 0 0 -2.3554</pose>
      <inertial>
        <pose frame=''>0.017792 -3.6e-05 -0.048313 0 -0 0</pose>
        <mass>0.170868</mass>
        <inertia>
          <ixx>0.000589379</ixx>
          <ixy>3.67753e-09</ixy>
          <ixz>-6.30008e-05</ixz>
          <iyy>0.000541032</iyy>
          <iyz>-9.23625e-09</iyz>
          <izz>8.24623e-05</izz>
        </inertia>
      </inertial>
      <collision name='Tibia_4_collision'>
        <pose frame=''>0 0 0 0 -0 0</pose>
        <geometry>
          <mesh>
            <scale>1 1 1</scale>
            <uri>model://jebediah/meshes/Tibia_4.STL</uri>
          </mesh>
        </geometry>
      </collision>
      <visual name='Tibia_4_visual'>
        <pose frame=''>0 0 0 0 -0 0</pose>
        <geometry>
          <mesh>
            <scale>1 1 1</scale>
            <uri>model://jebediah/meshes/Tibia_4.STL</uri>
          </mesh>
        </geometry>
      </visual>
    </link>
    <joint name='Servo_Femur_4_2' type='revolute'>
      <child>Tibia_4</child>
      <parent>Femur_4</parent>
      <axis>
        <xyz>0.707668 -0.706545 0</xyz>
        <limit>
          <lower>-1.4</lower>
          <upper>1.4</upper>
          <effort>0.9</effort>
          <velocity>5</velocity>
        </limit>
        <dynamics>
          <spring_reference>0</spring_reference>
          <spring_stiffness>0</spring_stiffness>
        </dynamics>
        <use_parent_model_frame>1</use_parent_model_frame>
      </axis>
    </joint>
    <link name='Coxa_1'>
      <pose frame=''>0.064888 -0.069996 -0.034543 0 -0 -0.78456</pose>
      <inertial>
        <pose frame=''>0.01481 -2.2e-05 0.029381 0 -0 0</pose>
        <mass>0.124104</mass>
        <inertia>
          <ixx>8.18267e-05</ixx>
          <ixy>-1.14316e-08</ixy>
          <ixz>6.1428e-07</ixz>
          <iyy>7.27029e-05</iyy>
          <iyz>2.00528e-08</iyz>
          <izz>0.000120694</izz>
        </inertia>
      </inertial>
      <collision name='Coxa_1_collision'>
        <pose frame=''>0 0 0 0 -0 0</pose>
        <geometry>
          <mesh>
            <scale>1 1 1</scale>
            <uri>model://jebediah/meshes/Coxa_1.STL</uri>
          </mesh>
        </geometry>
      </collision>
      <visual name='Coxa_1_visual'>
        <pose frame=''>0 0 0 0 -0 0</pose>
        <geometry>
          <mesh>
            <scale>1 1 1</scale>
            <uri>model://jebediah/meshes/Coxa_1.STL</uri>
          </mesh>
        </geometry>
      </visual>
    </link>
    <joint name='Servo_Coxa_1' type='revolute'>
      <child>Coxa_1</child>
      <parent>base_link</parent>
      <axis>
        <xyz>-0 0 1</xyz>
        <limit>
          <lower>-1.4</lower>
          <upper>1.4</upper>
          <effort>0.9</effort>
          <velocity>5</velocity>
        </limit>
        <dynamics>
          <spring_reference>0</spring_reference>
          <spring_stiffness>0</spring_stiffness>
        </dynamics>
        <use_parent_model_frame>1</use_parent_model_frame>
      </axis>
    </joint>
    <link name='Femur_1'>
      <pose frame=''>0.090573 -0.135795 -0.005543 0 -0 -0.78456</pose>
      <inertial>
        <pose frame=''>0.051468 0.026889 1.6e-05 0 -0 0</pose>
        <mass>0.158176</mass>
        <inertia>
          <ixx>8.72873e-05</ixx>
          <ixy>1.35181e-10</ixy>
          <ixz>-6.32792e-12</ixz>
          <iyy>0.000251934</iyy>
          <iyz>-3.84978e-08</iyz>
          <izz>0.000324907</izz>
        </inertia>
      </inertial>
      <collision name='Femur_1_collision'>
        <pose frame=''>0 0 0 0 -0 0</pose>
        <geometry>
          <mesh>
            <scale>1 1 1</scale>
            <uri>model://jebediah/meshes/Femur_1.STL</uri>
          </mesh>
        </geometry>
      </collision>
      <visual name='Femur_1_visual'>
        <pose frame=''>0 0 0 0 -0 0</pose>
        <geometry>
          <mesh>
            <scale>1 1 1</scale>
            <uri>model://jebediah/meshes/Femur_1.STL</uri>
          </mesh>
        </geometry>
      </visual>
    </link>
    <joint name='Servo_Femur_1_1' type='revolute'>
      <child>Femur_1</child>
      <parent>Coxa_1</parent>
      <axis>
        <xyz>0.706514 0.707699 0</xyz>
        <limit>
          <lower>-1.4</lower>
          <upper>1.4</upper>
          <effort>0.9</effort>
          <velocity>5</velocity>
        </limit>
        <dynamics>
          <spring_reference>0</spring_reference>
          <spring_stiffness>0</spring_stiffness>
        </dynamics>
        <use_parent_model_frame>1</use_parent_model_frame>
      </axis>
    </joint>
    <link name='Tibia_1'>
      <pose frame=''>0.183502 -0.188411 -0.005543 0 -0 -0.78456</pose>
      <inertial>
        <pose frame=''>0.017792 -3.6e-05 -0.048313 0 -0 0</pose>
        <mass>0.170868</mass>
        <inertia>
          <ixx>0.000589379</ixx>
          <ixy>3.67753e-09</ixy>
          <ixz>-6.30008e-05</ixz>
          <iyy>0.000541032</iyy>
          <iyz>-9.23621e-09</iyz>
          <izz>8.24623e-05</izz>
        </inertia>
      </inertial>
      <collision name='Tibia_1_collision'>
        <pose frame=''>0 0 0 0 -0 0</pose>
        <geometry>
          <mesh>
            <scale>1 1 1</scale>
            <uri>model://jebediah/meshes/Tibia_1.STL</uri>
          </mesh>
        </geometry>
      </collision>
      <visual name='Tibia_1_visual'>
        <pose frame=''>0 0 0 0 -0 0</pose>
        <geometry>
          <mesh>
            <scale>1 1 1</scale>
            <uri>model://jebediah/meshes/Tibia_1.STL</uri>
          </mesh>
        </geometry>
      </visual>
    </link>
    <joint name='Servo_Femur_1_2' type='revolute'>
      <child>Tibia_1</child>
      <parent>Femur_1</parent>
      <axis>
        <xyz>0.706514 0.707699 0</xyz>
        <limit>
          <lower>-1.4</lower>
          <upper>1.4</upper>
          <effort>0.9</effort>
          <velocity>5</velocity>
        </limit>
        <dynamics>
          <spring_reference>0</spring_reference>
          <spring_stiffness>0</spring_stiffness>
        </dynamics>
        <use_parent_model_frame>1</use_parent_model_frame>
      </axis>
    </joint>
    <link name='Coxa_2'>
      <pose frame=''>0.064888 0.070004 -0.034543 -0 -0 0.78623</pose>
      <inertial>
        <pose frame=''>0.01481 -2.2e-05 0.029381 0 -0 0</pose>
        <mass>0.124104</mass>
        <inertia>
          <ixx>8.18267e-05</ixx>
          <ixy>-1.14316e-08</ixy>
          <ixz>6.1428e-07</ixz>
          <iyy>7.27029e-05</iyy>
          <iyz>2.00528e-08</iyz>
          <izz>0.000120694</izz>
        </inertia>
      </inertial>
      <collision name='Coxa_2_collision'>
        <pose frame=''>0 0 0 0 -0 0</pose>
        <geometry>
          <mesh>
            <scale>1 1 1</scale>
            <uri>model://jebediah/meshes/Coxa_2.STL</uri>
          </mesh>
        </geometry>
      </collision>
      <visual name='Coxa_2_visual'>
        <pose frame=''>0 0 0 0 -0 0</pose>
        <geometry>
          <mesh>
            <scale>1 1 1</scale>
            <uri>model://jebediah/meshes/Coxa_2.STL</uri>
          </mesh>
        </geometry>
      </visual>
    </link>
    <joint name='Servo_Coxa_2' type='revolute'>
      <child>Coxa_2</child>
      <parent>base_link</parent>
      <axis>
        <xyz>-0 0 1</xyz>
        <limit>
          <lower>-1.4</lower>
          <upper>1.4</upper>
          <effort>0.9</effort>
          <velocity>5</velocity>
        </limit>
        <dynamics>
          <spring_reference>0</spring_reference>
          <spring_stiffness>0</spring_stiffness>
        </dynamics>
        <use_parent_model_frame>1</use_parent_model_frame>
      </axis>
    </joint>
    <link name='Femur_2'>
      <pose frame=''>0.130687 0.095689 -0.005543 -0 -0 0.78623</pose>
      <inertial>
        <pose frame=''>0.051468 0.026889 1.6e-05 0 -0 0</pose>
        <mass>0.158176</mass>
        <inertia>
          <ixx>8.72873e-05</ixx>
          <ixy>1.35178e-10</ixy>
          <ixz>-6.32836e-12</ixz>
          <iyy>0.000251934</iyy>
          <iyz>-3.84978e-08</iyz>
          <izz>0.000324907</izz>
        </inertia>
      </inertial>
      <collision name='Femur_2_collision'>
        <pose frame=''>0 0 0 0 -0 0</pose>
        <geometry>
          <mesh>
            <scale>1 1 1</scale>
            <uri>model://jebediah/meshes/Femur_2.STL</uri>
          </mesh>
        </geometry>
      </collision>
      <visual name='Femur_2_visual'>
        <pose frame=''>0 0 0 0 -0 0</pose>
        <geometry>
          <mesh>
            <scale>1 1 1</scale>
            <uri>model://jebediah/meshes/Femur_2.STL</uri>
          </mesh>
        </geometry>
      </visual>
    </link>
    <joint name='Servo_Femur_2_1' type='revolute'>
      <child>Femur_2</child>
      <parent>Coxa_2</parent>
      <axis>
        <xyz>0.707695 -0.706518 0</xyz>
        <limit>
          <lower>-1.4</lower>
          <upper>1.4</upper>
          <effort>0.9</effort>
          <velocity>5</velocity>
        </limit>
        <dynamics>
          <spring_reference>0</spring_reference>
          <spring_stiffness>0</spring_stiffness>
        </dynamics>
        <use_parent_model_frame>1</use_parent_model_frame>
      </axis>
    </joint>
    <link name='Tibia_2'>
      <pose frame=''>0.183304 0.188617 -0.005543 -0 -0 0.78623</pose>
      <inertial>
        <pose frame=''>0.017792 -3.6e-05 -0.048313 0 -0 0</pose>
        <mass>0.170868</mass>
        <inertia>
          <ixx>0.000589379</ixx>
          <ixy>3.68459e-09</ixy>
          <ixz>-6.30008e-05</ixz>
          <iyy>0.000541032</iyy>
          <iyz>-9.2363e-09</iyz>
          <izz>8.24623e-05</izz>
        </inertia>
      </inertial>
      <collision name='Tibia_2_collision'>
        <pose frame=''>0 0 0 0 -0 0</pose>
        <geometry>
          <mesh>
            <scale>1 1 1</scale>
            <uri>model://jebediah/meshes/Tibia_2.STL</uri>
          </mesh>
        </geometry>
      </collision>
      <visual name='Tibia_2_visual'>
        <pose frame=''>0 0 0 0 -0 0</pose>
        <geometry>
          <mesh>
            <scale>1 1 1</scale>
            <uri>model://jebediah/meshes/Tibia_2.STL</uri>
          </mesh>
        </geometry>
      </visual>
    </link>
    <joint name='Servo_Femur_2_2' type='revolute'>
      <child>Tibia_2</child>
      <parent>Femur_2</parent>
      <axis>
        <xyz>0.707695 -0.706518 0</xyz>
        <limit>
          <lower>-1.4</lower>
          <upper>1.4</upper>
          <effort>0.9</effort>
          <velocity>5</velocity>
        </limit>
        <dynamics>
          <spring_reference>0</spring_reference>
          <spring_stiffness>0</spring_stiffness>
        </dynamics>
        <use_parent_model_frame>1</use_parent_model_frame>
      </axis>
    </joint>
    <link name='Coxa_3'>
      <pose frame=''>-0.075112 0.070004 -0.034543 -0 0 2.357</pose>
      <inertial>
        <pose frame=''>0.01481 -2.2e-05 0.029381 0 -0 0</pose>
        <mass>0.124104</mass>
        <inertia>
          <ixx>8.18267e-05</ixx>
          <ixy>-1.14302e-08</ixy>
          <ixz>6.1428e-07</ixz>
          <iyy>7.27029e-05</iyy>
          <iyz>2.00526e-08</iyz>
          <izz>0.000120694</izz>
        </inertia>
      </inertial>
      <collision name='Coxa_3_collision'>
        <pose frame=''>0 0 0 0 -0 0</pose>
        <geometry>
          <mesh>
            <scale>1 1 1</scale>
            <uri>model://jebediah/meshes/Coxa_3.STL</uri>
          </mesh>
        </geometry>
      </collision>
      <visual name='Coxa_3_visual'>
        <pose frame=''>0 0 0 0 -0 0</pose>
        <geometry>
          <mesh>
            <scale>1 1 1</scale>
            <uri>model://jebediah/meshes/Coxa_3.STL</uri>
          </mesh>
        </geometry>
      </visual>
    </link>
    <joint name='Servo_Coxa_3' type='revolute'>
      <child>Coxa_3</child>
      <parent>base_link</parent>
      <axis>
        <xyz>-0 -0 1</xyz>
        <limit>
          <lower>-1.4</lower>
          <upper>1.4</upper>
          <effort>0.9</effort>
          <velocity>5</velocity>
        </limit>
        <dynamics>
          <spring_reference>0</spring_reference>
          <spring_stiffness>0</spring_stiffness>
        </dynamics>
        <use_parent_model_frame>1</use_parent_model_frame>
      </axis>
    </joint>
    <link name='Femur'>
      <pose frame=''>-0.100795 0.135804 -0.005543 -0 0 2.357</pose>
      <inertial>
        <pose frame=''>0.051468 0.026889 1.6e-05 0 -0 0</pose>
        <mass>0.158176</mass>
        <inertia>
          <ixx>8.72873e-05</ixx>
          <ixy>1.35183e-10</ixy>
          <ixz>-6.32861e-12</ixz>
          <iyy>0.000251934</iyy>
          <iyz>-3.84978e-08</iyz>
          <izz>0.000324907</izz>
        </inertia>
      </inertial>
      <collision name='Femur_collision'>
        <pose frame=''>0 0 0 0 -0 0</pose>
        <geometry>
          <mesh>
            <scale>1 1 1</scale>
            <uri>model://jebediah/meshes/Femur.STL</uri>
          </mesh>
        </geometry>
      </collision>
      <visual name='Femur_visual'>
        <pose frame=''>0 0 0 0 -0 0</pose>
        <geometry>
          <mesh>
            <scale>1 1 1</scale>
            <uri>model://jebediah/meshes/Femur.STL</uri>
          </mesh>
        </geometry>
      </visual>
    </link>
    <joint name='Servo_Femur_3_1' type='revolute'>
      <child>Femur</child>
      <parent>Coxa_3</parent>
      <axis>
        <xyz>0.706537 0.707676 0</xyz>
        <limit>
          <lower>-1.4</lower>
          <upper>1.4</upper>
          <effort>0.9</effort>
          <velocity>5</velocity>
        </limit>
        <dynamics>
          <spring_reference>0</spring_reference>
          <spring_stiffness>0</spring_stiffness>
        </dynamics>
        <use_parent_model_frame>1</use_parent_model_frame>
      </axis>
    </joint>
    <link name='Tibia_3'>
      <pose frame=''>-0.193722 0.188423 -0.005543 -0 0 2.357</pose>
      <inertial>
        <pose frame=''>0.017792 -3.6e-05 -0.048313 0 -0 0</pose>
        <mass>0.170868</mass>
        <inertia>
          <ixx>0.000589379</ixx>
          <ixy>3.6838e-09</ixy>
          <ixz>-6.30008e-05</ixz>
          <iyy>0.000541032</iyy>
          <iyz>-9.2364e-09</iyz>
          <izz>8.24623e-05</izz>
        </inertia>
      </inertial>
      <collision name='Tibia_3_collision'>
        <pose frame=''>0 0 0 0 -0 0</pose>
        <geometry>
          <mesh>
            <scale>1 1 1</scale>
            <uri>model://jebediah/meshes/Tibia_3.STL</uri>
          </mesh>
        </geometry>
      </collision>
      <visual name='Tibia_3_visual'>
        <pose frame=''>0 0 0 0 -0 0</pose>
        <geometry>
          <mesh>
            <scale>1 1 1</scale>
            <uri>model://jebediah/meshes/Tibia_3.STL</uri>
          </mesh>
        </geometry>
      </visual>
    </link>
    <joint name='Servo_Femur_3_2' type='revolute'>
      <child>Tibia_3</child>
      <parent>Femur</parent>
      <axis>
        <xyz>0.706537 0.707676 0</xyz>
        <limit>
          <lower>-1.4</lower>
          <upper>1.4</upper>
          <effort>0.9</effort>
          <velocity>5</velocity>
        </limit>
        <dynamics>
          <spring_reference>0</spring_reference>
          <spring_stiffness>0</spring_stiffness>
        </dynamics>
        <use_parent_model_frame>1</use_parent_model_frame>
      </axis>
    </joint>
  </model>
</sdf>
