<robot
  name="jebediah">
  <origin
    xyz="0 0 0.1677"/>
  <link
    name="base_link">
    <inertial>
      <origin
        xyz="1.44173913307899E-07 9.5258129717557E-09 1.51352445312836E-07"
        rpy="0 0 0" />
      <mass
        value="0.297355206086086" />
      <inertia
        ixx="0.00102327912793897"
        ixy="-1.0923296250537E-06"
        ixz="-1.70446477679888E-05"
        iyy="0.00112581981927501"
        iyz="-2.26628873195509E-07"
        izz="0.00147666342611158" />
    </inertial>
    <visual>
      <origin
        xyz="0 0 0"
        rpy="0 0 0" />
      <geometry>
        <mesh
          filename="package://jebediah/meshes/base_link.stl" />
      </geometry>
      <material
        name="">
        <color
          rgba="0 0 0 1" />
      </material>
    </visual>
    <collision>
      <origin
        xyz="0 0 0"
        rpy="0 0 0" />
      <geometry>
        <mesh
          filename="package://jebediah/meshes/base_link_collision.stl" />
      </geometry>
    </collision>
  </link>
  <link
    name="Coxa_1">
    <inertial>
      <origin
        xyz="0.0148101329514558 -2.1902843745078E-05 0.0293805312518355"
        rpy="0 0 0" />
      <mass
        value="0.12410445572477" />
      <inertia
        ixx="8.18267102127417E-05"
        ixy="-1.14315933549453E-08"
        ixz="6.14280187684567E-07"
        iyy="7.27029261791945E-05"
        iyz="2.00528242625429E-08"
        izz="0.000120694100470356" />
    </inertial>
    <visual>
      <origin
        xyz="0 0 0"
        rpy="0 0 0" />
      <geometry>
        <mesh
          filename="package://jebediah/meshes/Coxa.stl" />
      </geometry>
      <material
        name="">
        <color
          rgba="0.752941176470588 0.752941176470588 0.752941176470588 1" />
      </material>
    </visual>
    <collision>
      <origin
        xyz="0 0 0"
        rpy="0 0 0" />
      <geometry>
        <mesh
          filename="package://jebediah/meshes/Coxa_Collision.stl" />
      </geometry>
    </collision>
  </link>
  <joint
    name="Servo_Coxa_1"
    type="revolute">
    <origin
      xyz="0.064888 -0.069996 -0.034543"
      rpy="7.3215E-15 -7.4127E-15 -0.78456" />
    <parent
      link="base_link" />
    <child
      link="Coxa_1" />
    <axis
      xyz="0 0 1" />
    <limit
      lower="-1.4"
      upper="1.4"
      effort="0.9"
      velocity="5" />
  </joint>
  <link
    name="Femur_1">
    <inertial>
      <origin
        xyz="0.0514683645082641 0.0268892828548302 1.60365581410998E-05"
        rpy="0 0 0" />
      <mass
        value="0.158175969008051" />
      <inertia
        ixx="8.72872740681003E-05"
        ixy="1.35181067647126E-10"
        ixz="-6.3279240787435E-12"
        iyy="0.000251933770808422"
        iyz="-3.84978191823943E-08"
        izz="0.000324907463142007" />
    </inertial>
    <visual>
      <origin
        xyz="0 0 0"
        rpy="0 0 0" />
      <geometry>
        <mesh
          filename="package://jebediah/meshes/Femur.stl" />
      </geometry>
      <material
        name="">
        <color
          rgba="0.752941176470588 0.752941176470588 0.752941176470588 1" />
      </material>
    </visual>
    <collision>
      <origin
        xyz="0 0 0"
        rpy="0 0 0" />
      <geometry>
        <mesh
          filename="package://jebediah/meshes/Femur_Collision.stl" />
      </geometry>
    </collision>
  </link>
  <joint
    name="Servo_Femur_1_1"
    type="revolute">
    <origin
      xyz="0.064665 -0.028419 0.029"
      rpy="-1.3192E-16 -2.7756E-17 -2.7756E-16" />
    <parent
      link="Coxa_1" />
    <child
      link="Femur_1" />
    <axis
      xyz="0 1 0" />
    <limit
      lower="-1.4"
      upper="1.4"
      effort="0.9"
      velocity="5" />
  </joint>
  <link
    name="Tibia_1">
    <inertial>
      <origin
        xyz="0.0177922229662775 -3.62758954459419E-05 -0.0483129162205185"
        rpy="0 0 0" />
      <mass
        value="0.170868331501115" />
      <inertia
        ixx="0.000589378727235705"
        ixy="3.67753470546182E-09"
        ixz="-6.30008131376603E-05"
        iyy="0.000541031911991726"
        iyz="-9.23620994011666E-09"
        izz="8.24622957395783E-05" />
    </inertial>
    <visual>
      <origin
        xyz="0 0 0"
        rpy="0 0 0" />
      <geometry>
        <mesh
          filename="package://jebediah/meshes/Tibia.stl" />
      </geometry>
      <material
        name="">
        <color
          rgba="0.101960784313725 0.101960784313725 0.101960784313725 1" />
      </material>
    </visual>
    <collision>
      <origin
        xyz="0 0 0"
        rpy="0 0 0" />
      <geometry>
        <mesh
          filename="package://jebediah/meshes/Tibia_Collision.stl" />
      </geometry>
    </collision>
  </link>
  <joint
    name="Servo_Femur_1_2"
    type="revolute">
    <origin
      xyz="0.10294 0.028419 0"
      rpy="8.3049E-16 2.7756E-17 5.3294E-29" />
    <parent
      link="Femur_1" />
    <child
      link="Tibia_1" />
    <axis
      xyz="0 1 0" />
    <limit
      lower="-1.4"
      upper="1.4"
      effort="0.9"
      velocity="5" />
  </joint>
  <link
    name="Coxa_2">
    <inertial>
      <origin
        xyz="0.0148101329517311 -2.19028429722379E-05 0.0293805312515441"
        rpy="0 0 0" />
      <mass
        value="0.124104455718357" />
      <inertia
        ixx="8.18267102017881E-05"
        ixy="-1.14315989131767E-08"
        ixz="6.14280187527743E-07"
        iyy="7.27029261747406E-05"
        iyz="2.00528247122634E-08"
        izz="0.000120694100456064" />
    </inertial>
    <visual>
      <origin
        xyz="0 0 0"
        rpy="0 0 0" />
      <geometry>
        <mesh
          filename="package://jebediah/meshes/Coxa.stl" />
      </geometry>
      <material
        name="">
        <color
          rgba="0.752941176470588 0.752941176470588 0.752941176470588 1" />
      </material>
    </visual>
    <collision>
      <origin
        xyz="0 0 0"
        rpy="0 0 0" />
      <geometry>
        <mesh
          filename="package://jebediah/meshes/Coxa_Collision.stl" />
      </geometry>
    </collision>
  </link>
  <joint
    name="Servo_Coxa_2"
    type="revolute">
    <origin
      xyz="0.064888 0.070004 -0.034543"
      rpy="-7.4916E-15 -7.4004E-15 0.78623" />
    <parent
      link="base_link" />
    <child
      link="Coxa_2" />
    <axis
      xyz="0 0 1" />
    <limit
      lower="-1.4"
      upper="1.4"
      effort="0.9"
      velocity="5" />
  </joint>
  <link
    name="Femur_2">
    <inertial>
      <origin
        xyz="0.0514683645078939 0.0268892828552024 1.60365582139443E-05"
        rpy="0 0 0" />
      <mass
        value="0.158175969006612" />
      <inertia
        ixx="8.72872740651651E-05"
        ixy="1.35178300983411E-10"
        ixz="-6.32836486836297E-12"
        iyy="0.000251933770805777"
        iyz="-3.84978186970565E-08"
        izz="0.000324907463136718" />
    </inertial>
    <visual>
      <origin
        xyz="0 0 0"
        rpy="0 0 0" />
      <geometry>
        <mesh
          filename="package://jebediah/meshes/Femur.stl" />
      </geometry>
      <material
        name="">
        <color
          rgba="0.752941176470588 0.752941176470588 0.752941176470588 1" />
      </material>
    </visual>
    <collision>
      <origin
        xyz="0 0 0"
        rpy="0 0 0" />
      <geometry>
        <mesh
          filename="package://jebediah/meshes/Femur_Collision.stl" />
      </geometry>
    </collision>
  </link>
  <joint
    name="Servo_Femur_2_1"
    type="revolute">
    <origin
      xyz="0.064665 -0.028419 0.029"
      rpy="-1.3192E-16 -2.7756E-17 -3.3307E-16" />
    <parent
      link="Coxa_2" />
    <child
      link="Femur_2" />
    <axis
      xyz="0 -1 0" />
    <limit
      lower="-1.4"
      upper="1.4"
      effort="0.9"
      velocity="5" />
  </joint>
  <link
    name="Tibia_2">
    <inertial>
      <origin
        xyz="0.0177922229561469 -3.62749421672914E-05 -0.0483129162263953"
        rpy="0 0 0" />
      <mass
        value="0.170868347804751" />
      <inertia
        ixx="0.000589378734851685"
        ixy="3.68459478726201E-09"
        ixz="-6.30008134388682E-05"
        iyy="0.000541031918070153"
        iyz="-9.2363030417831E-09"
        izz="8.24623078851052E-05" />
    </inertial>
    <visual>
      <origin
        xyz="0 0 0"
        rpy="0 0 0" />
      <geometry>
        <mesh
          filename="package://jebediah/meshes/Tibia.stl" />
      </geometry>
      <material
        name="">
        <color
          rgba="0.101960784313725 0.101960784313725 0.101960784313725 1" />
      </material>
    </visual>
    <collision>
      <origin
        xyz="0 0 0"
        rpy="0 0 0" />
      <geometry>
        <mesh
          filename="package://jebediah/meshes/Tibia_Collision.stl" />
      </geometry>
    </collision>
  </link>
  <joint
    name="Servo_Femur_2_2"
    type="revolute">
    <origin
      xyz="0.10294 0.028419 0"
      rpy="8.3049E-16 2.7756E-17 -5.6417E-29" />
    <parent
      link="Femur_2" />
    <child
      link="Tibia_2" />
    <axis
      xyz="0 -1 0" />
    <limit
      lower="-1.4"
      upper="1.4"
      effort="0.9"
      velocity="5" />
  </joint>
  <link
    name="Coxa_3">
    <inertial>
      <origin
        xyz="0.0148101326570277 -2.19023552313902E-05 0.0293805312697344"
        rpy="0 0 0" />
      <mass
        value="0.124104457423663" />
      <inertia
        ixx="8.18267125215861E-05"
        ixy="-1.14302324413302E-08"
        ixz="6.14280354579498E-07"
        iyy="7.27029270224408E-05"
        iyz="2.00526271048197E-08"
        izz="0.000120694103697151" />
    </inertial>
    <visual>
      <origin
        xyz="0 0 0"
        rpy="0 0 0" />
      <geometry>
        <mesh
          filename="package://jebediah/meshes/Coxa.stl" />
      </geometry>
      <material
        name="">
        <color
          rgba="0.752941176470588 0.752941176470588 0.752941176470588 1" />
      </material>
    </visual>
    <collision>
      <origin
        xyz="0 0 0"
        rpy="0 0 0" />
      <geometry>
        <mesh
          filename="package://jebediah/meshes/Coxa_Collision.stl" />
      </geometry>
    </collision>
  </link>
  <joint
    name="Servo_Coxa_3"
    type="revolute">
    <origin
      xyz="-0.075112 0.070004 -0.034543"
      rpy="-7.4792E-15 7.4127E-15 2.357" />
    <parent
      link="base_link" />
    <child
      link="Coxa_3" />
    <axis
      xyz="0 0 1" />
    <limit
      lower="-1.4"
      upper="1.4"
      effort="0.9"
      velocity="5" />
  </joint>
  <link
    name="Femur">
    <inertial>
      <origin
        xyz="0.0514683645077476 0.0268892828552327 1.60365582145272E-05"
        rpy="0 0 0" />
      <mass
        value="0.158175969006369" />
      <inertia
        ixx="8.72872740646768E-05"
        ixy="1.35183478655545E-10"
        ixz="-6.32861209229775E-12"
        iyy="0.000251933770805324"
        iyz="-3.84978183221189E-08"
        izz="0.000324907463135824" />
    </inertial>
    <visual>
      <origin
        xyz="0 0 0"
        rpy="0 0 0" />
      <geometry>
        <mesh
          filename="package://jebediah/meshes/Femur.stl" />
      </geometry>
      <material
        name="">
        <color
          rgba="0.752941176470588 0.752941176470588 0.752941176470588 1" />
      </material>
    </visual>
    <collision>
      <origin
        xyz="0 0 0"
        rpy="0 0 0" />
      <geometry>
        <mesh
          filename="package://jebediah/meshes/Femur_Collision.stl" />
      </geometry>
    </collision>
  </link>
  <joint
    name="Servo_Femur_3_1"
    type="revolute">
    <origin
      xyz="0.064665 -0.028419 0.029"
      rpy="-1.3192E-16 -2.7756E-17 -3.3307E-16" />
    <parent
      link="Coxa_3" />
    <child
      link="Femur" />
    <axis
      xyz="0 -1 0" />
    <limit
      lower="-1.4"
      upper="1.4"
      effort="0.9"
      velocity="5" />
  </joint>
  <link
    name="Tibia_3">
    <inertial>
      <origin
        xyz="0.0177922232663992 -3.62750899647185E-05 -0.0483129161448379"
        rpy="0 0 0" />
      <mass
        value="0.170868354393158" />
      <inertia
        ixx="0.000589378732711979"
        ixy="3.68380068005006E-09"
        ixz="-6.30008133875489E-05"
        iyy="0.000541031916342638"
        iyz="-9.23640343546084E-09"
        izz="8.24623050717877E-05" />
    </inertial>
    <visual>
      <origin
        xyz="0 0 0"
        rpy="0 0 0" />
      <geometry>
        <mesh
          filename="package://jebediah/meshes/Tibia.stl" />
      </geometry>
      <material
        name="">
        <color
          rgba="0.101960784313725 0.101960784313725 0.101960784313725 1" />
      </material>
    </visual>
    <collision>
      <origin
        xyz="0 0 0"
        rpy="0 0 0" />
      <geometry>
        <mesh
          filename="package://jebediah/meshes/Tibia_Collision.stl" />
      </geometry>
    </collision>
  </link>
  <joint
    name="Servo_Femur_3_2"
    type="revolute">
    <origin
      xyz="0.10294 0.028419 0"
      rpy="8.3049E-16 2.7756E-17 5.6419E-29" />
    <parent
      link="Femur" />
    <child
      link="Tibia_3" />
    <axis
      xyz="0 -1 0" />
    <limit
      lower="-1.4"
      upper="1.4"
      effort="0.9"
      velocity="5" />
  </joint>
  <link
    name="Coxa_4">
    <inertial>
      <origin
        xyz="0.0148101329345743 -2.19028378360409E-05 0.029380531226478"
        rpy="0 0 0" />
      <mass
        value="0.124104456070875" />
      <inertia
        ixx="8.18267107587151E-05"
        ixy="-1.14318477477996E-08"
        ixz="6.14280170284984E-07"
        iyy="7.27029262506899E-05"
        iyz="2.00528307914144E-08"
        izz="0.000120694101201601" />
    </inertial>
    <visual>
      <origin
        xyz="0 0 0"
        rpy="0 0 0" />
      <geometry>
        <mesh
          filename="package://jebediah/meshes/Coxa.stl" />
      </geometry>
      <material
        name="">
        <color
          rgba="0.752941176470588 0.752941176470588 0.752941176470588 1" />
      </material>
    </visual>
    <collision>
      <origin
        xyz="0 0 0"
        rpy="0 0 0" />
      <geometry>
        <mesh
          filename="package://jebediah/meshes/Coxa_Collision.stl" />
      </geometry>
    </collision>
  </link>
  <joint
    name="Serv_Coxa_4"
    type="revolute">
    <origin
      xyz="-0.075112 -0.069996 -0.034543"
      rpy="7.3339E-15 7.4004E-15 -2.3554" />
    <parent
      link="base_link" />
    <child
      link="Coxa_4" />
    <axis
      xyz="0 0 1" />
    <limit
      lower="-1.4"
      upper="1.4"
      effort="0.9"
      velocity="5" />
  </joint>
  <link
    name="Femur_4">
    <inertial>
      <origin
        xyz="0.0514683645074522 0.0268892828547454 1.60365581585997E-05"
        rpy="0 0 0" />
      <mass
        value="0.158175969007339" />
      <inertia
        ixx="8.72872740667591E-05"
        ixy="1.35179148138616E-10"
        ixz="-6.32898688153183E-12"
        iyy="0.000251933770806947"
        iyz="-3.84978194716861E-08"
        izz="0.000324907463139296" />
    </inertial>
    <visual>
      <origin
        xyz="0 0 0"
        rpy="0 0 0" />
      <geometry>
        <mesh
          filename="package://jebediah/meshes/Femur.stl" />
      </geometry>
      <material
        name="">
        <color
          rgba="0.752941176470588 0.752941176470588 0.752941176470588 1" />
      </material>
    </visual>
    <collision>
      <origin
        xyz="0 0 0"
        rpy="0 0 0" />
      <geometry>
        <mesh
          filename="package://jebediah/meshes/Femur_Collision.stl" />
      </geometry>
    </collision>
  </link>
  <joint
    name="Servo_Femur_4_1"
    type="revolute">
    <origin
      xyz="0.064665 -0.028419 0.029"
      rpy="-1.3192E-16 -2.7756E-17 -2.7756E-16" />
    <parent
      link="Coxa_4" />
    <child
      link="Femur_4" />
    <axis
      xyz="0 1 0" />
    <limit
      lower="-1.4"
      upper="1.4"
      effort="0.9"
      velocity="5" />
  </joint>
  <link
    name="Tibia_4">
    <inertial>
      <origin
        xyz="0.0177922229702461 -3.62758977275057E-05 -0.0483129162061354"
        rpy="0 0 0" />
      <mass
        value="0.170868331464115" />
      <inertia
        ixx="0.000589378727123221"
        ixy="3.67752621924847E-09"
        ixz="-6.30008130993154E-05"
        iyy="0.000541031911870598"
        iyz="-9.23624642233622E-09"
        izz="8.24622957251046E-05" />
    </inertial>
    <visual>
      <origin
        xyz="0 0 0"
        rpy="0 0 0" />
      <geometry>
        <mesh
          filename="package://jebediah/meshes/Tibia.stl" />
      </geometry>
      <material
        name="">
        <color
          rgba="0.101960784313725 0.101960784313725 0.101960784313725 1" />
      </material>
    </visual>
    <collision>
      <origin
        xyz="0 0 0"
        rpy="0 0 0" />
      <geometry>
        <mesh
          filename="package://jebediah/meshes/Tibia_Collision.stl" />
      </geometry>
    </collision>
  </link>
  <joint
    name="Servo_Femur_4_2"
    type="revolute">
    <origin
      xyz="0.10294 0.028419 0"
      rpy="8.3049E-16 2.7756E-17 -5.3297E-29" />
    <parent
      link="Femur_4" />
    <child
      link="Tibia_4" />
    <axis
      xyz="0 1 0" />
    <limit
      lower="-1.4"
      upper="1.4"
      effort="0.9"
      velocity="5" />
</robot>