<robot
  name="jebediah">
  <link
    name="base_link">
    <inertial>
      <origin
        xyz="0 0 1"
        rpy="0 0 0" />
      <mass
        value="0.29736" />
      <inertia
        ixx="0.0010233"
        ixy="-1.0923E-06"
        ixz="-1.7045E-05"
        iyy="0.0011258"
        iyz="-2.2663E-07"
        izz="0.0014767" />
    </inertial>
    <visual>
      <origin
        xyz="0 0 0"
        rpy="0 0 0" />
      <geometry>
        <mesh
          filename="package://jebediah/meshes/base_link.STL" />
      </geometry>
      <material
        name="">
        <color
          rgba="0.75294 0.75294 0.75294 1" />
      </material>
    </visual>
    <collision>
      <origin
        xyz="0 0 0"
        rpy="0 0 0" />
      <geometry>
        <mesh
          filename="package://jebediah/meshes/base_link.STL" />
      </geometry>
    </collision>
  </link>
  <link
    name="Coxa_1">
    <inertial>
      <origin
        xyz="-3.3267E-08 1.3025E-08 -7.3489E-10"
        rpy="0 0 0" />
      <mass
        value="0.1241" />
      <inertia
        ixx="8.1827E-05"
        ixy="-1.1432E-08"
        ixz="6.1428E-07"
        iyy="7.2703E-05"
        iyz="2.0053E-08"
        izz="0.00012069" />
    </inertial>
    <visual>
      <origin
        xyz="0 0 0"
        rpy="0 0 0" />
      <geometry>
        <mesh
          filename="package://jebediah/meshes/Coxa_1.STL" />
      </geometry>
      <material
        name="">
        <color
          rgba="0.75294 0.75294 0.75294 1" />
      </material>
    </visual>
    <collision>
      <origin
        xyz="0 0 0"
        rpy="0 0 0" />
      <geometry>
        <mesh
          filename="package://jebediah/meshes/Coxa_1.STL" />
      </geometry>
    </collision>
  </link>
  <joint
    name="Servo_Coxa_1"
    type="revolute">
    <origin
      xyz="0.075353 -0.080475 -0.0051626"
      rpy="7.3215E-15 -7.4127E-15 -0.78456" />
    <parent
      link="base_link" />
    <child
      link="Coxa_1" />
    <axis
      xyz="0 0 1" />
    <limit
      lower="-1.5708"
      upper="1.5708"
      effort="0.9"
      velocity="5" />
  </joint>
  <link
    name="Femur_1">
    <inertial>
      <origin
        xyz="-1.1433E-08 8.2829E-08 3.0068E-08"
        rpy="0 0 0" />
      <mass
        value="0.15818" />
      <inertia
        ixx="8.7287E-05"
        ixy="1.3518E-10"
        ixz="-6.3279E-12"
        iyy="0.00025193"
        iyz="-3.8498E-08"
        izz="0.00032491" />
    </inertial>
    <visual>
      <origin
        xyz="0 0 0"
        rpy="0 0 0" />
      <geometry>
        <mesh
          filename="package://jebediah/meshes/Femur_1.STL" />
      </geometry>
      <material
        name="">
        <color
          rgba="0.75294 0.75294 0.75294 1" />
      </material>
    </visual>
    <collision>
      <origin
        xyz="0 0 0"
        rpy="0 0 0" />
      <geometry>
        <mesh
          filename="package://jebediah/meshes/Femur_1.STL" />
      </geometry>
    </collision>
  </link>
  <joint
    name="Servo_Femur_1_1"
    type="revolute">
    <origin
      xyz="0.10132 -0.0015074 -0.00036453"
      rpy="-1.3192E-16 -2.7756E-17 -2.7756E-16" />
    <parent
      link="Coxa_1" />
    <child
      link="Femur_1" />
    <axis
      xyz="0 1 0" />
    <limit
      lower="-1.5708"
      upper="1.5708"
      effort="0.9"
      velocity="5" />
  </joint>
  <link
    name="Tibia_1">
    <inertial>
      <origin
        xyz="-7.3461E-08 -7.9163E-08 5.1192E-07"
        rpy="0 0 0" />
      <mass
        value="0.17087" />
      <inertia
        ixx="0.00058938"
        ixy="3.6775E-09"
        ixz="-6.3001E-05"
        iyy="0.00054103"
        iyz="-9.2362E-09"
        izz="8.2462E-05" />
    </inertial>
    <visual>
      <origin
        xyz="0 0 0"
        rpy="0 0 0" />
      <geometry>
        <mesh
          filename="package://jebediah/meshes/Tibia_1.STL" />
      </geometry>
      <material
        name="">
        <color
          rgba="0.10196 0.10196 0.10196 1" />
      </material>
    </visual>
    <collision>
      <origin
        xyz="0 0 0"
        rpy="0 0 0" />
      <geometry>
        <mesh
          filename="package://jebediah/meshes/Tibia_1.STL" />
      </geometry>
    </collision>
  </link>
  <joint
    name="Servo_Femur_1_2"
    type="revolute">
    <origin
      xyz="0.069261 0.0014932 -0.04833"
      rpy="8.3049E-16 2.7756E-17 5.3294E-29" />
    <parent
      link="Femur_1" />
    <child
      link="Tibia_1" />
    <axis
      xyz="0 1 0" />
    <limit
      lower="-1.5708"
      upper="1.5708"
      effort="0.9"
      velocity="5" />
  </joint>
  <link
    name="Coxa_2">
    <inertial>
      <origin
        xyz="-3.3266E-08 1.3026E-08 -7.3518E-10"
        rpy="0 0 0" />
      <mass
        value="0.1241" />
      <inertia
        ixx="8.1827E-05"
        ixy="-1.1432E-08"
        ixz="6.1428E-07"
        iyy="7.2703E-05"
        iyz="2.0053E-08"
        izz="0.00012069" />
    </inertial>
    <visual>
      <origin
        xyz="0 0 0"
        rpy="0 0 0" />
      <geometry>
        <mesh
          filename="package://jebediah/meshes/Coxa_2.STL" />
      </geometry>
      <material
        name="">
        <color
          rgba="0.75294 0.75294 0.75294 1" />
      </material>
    </visual>
    <collision>
      <origin
        xyz="0 0 0"
        rpy="0 0 0" />
      <geometry>
        <mesh
          filename="package://jebediah/meshes/Coxa_2.STL" />
      </geometry>
    </collision>
  </link>
  <joint
    name="Servo_Coxa_2"
    type="revolute">
    <origin
      xyz="0.075367 0.08047 -0.0051626"
      rpy="-7.4916E-15 -7.4004E-15 0.78623" />
    <parent
      link="base_link" />
    <child
      link="Coxa_2" />
    <axis
      xyz="0 0 1" />
    <limit
      lower="-1.5708"
      upper="1.5708"
      effort="0.9"
      velocity="5" />
  </joint>
  <link
    name="Femur_2">
    <inertial>
      <origin
        xyz="-1.1434E-08 8.283E-08 3.0068E-08"
        rpy="0 0 0" />
      <mass
        value="0.15818" />
      <inertia
        ixx="8.7287E-05"
        ixy="1.3518E-10"
        ixz="-6.3284E-12"
        iyy="0.00025193"
        iyz="-3.8498E-08"
        izz="0.00032491" />
    </inertial>
    <visual>
      <origin
        xyz="0 0 0"
        rpy="0 0 0" />
      <geometry>
        <mesh
          filename="package://jebediah/meshes/Femur_2.STL" />
      </geometry>
      <material
        name="">
        <color
          rgba="0.75294 0.75294 0.75294 1" />
      </material>
    </visual>
    <collision>
      <origin
        xyz="0 0 0"
        rpy="0 0 0" />
      <geometry>
        <mesh
          filename="package://jebediah/meshes/Femur_2.STL" />
      </geometry>
    </collision>
  </link>
  <joint
    name="Servo_Femur_2_1"
    type="revolute">
    <origin
      xyz="0.10132 -0.0015074 -0.00036453"
      rpy="-1.3192E-16 -2.7756E-17 -3.3307E-16" />
    <parent
      link="Coxa_2" />
    <child
      link="Femur_2" />
    <axis
      xyz="0 1 0" />
    <limit
      lower="-1.5708"
      upper="1.5708"
      effort="0.9"
      velocity="5" />
  </joint>
  <link
    name="Tibia_2">
    <inertial>
      <origin
        xyz="-7.3471E-08 -7.821E-08 5.1191E-07"
        rpy="0 0 0" />
      <mass
        value="0.17087" />
      <inertia
        ixx="0.00058938"
        ixy="3.6846E-09"
        ixz="-6.3001E-05"
        iyy="0.00054103"
        iyz="-9.2363E-09"
        izz="8.2462E-05" />
    </inertial>
    <visual>
      <origin
        xyz="0 0 0"
        rpy="0 0 0" />
      <geometry>
        <mesh
          filename="package://jebediah/meshes/Tibia_2.STL" />
      </geometry>
      <material
        name="">
        <color
          rgba="0.10196 0.10196 0.10196 1" />
      </material>
    </visual>
    <collision>
      <origin
        xyz="0 0 0"
        rpy="0 0 0" />
      <geometry>
        <mesh
          filename="package://jebediah/meshes/Tibia_2.STL" />
      </geometry>
    </collision>
  </link>
  <joint
    name="Servo_Femur_2_2"
    type="revolute">
    <origin
      xyz="0.069261 0.0014932 -0.04833"
      rpy="8.3049E-16 2.7756E-17 -5.6417E-29" />
    <parent
      link="Femur_2" />
    <child
      link="Tibia_2" />
    <axis
      xyz="0 1 0" />
    <limit
      lower="-1.5708"
      upper="1.5708"
      effort="0.9"
      velocity="0" />
  </joint>
  <link
    name="Coxa_3">
    <inertial>
      <origin
        xyz="-3.3561E-08 1.3513E-08 -7.1699E-10"
        rpy="0 0 0" />
      <mass
        value="0.1241" />
      <inertia
        ixx="8.1827E-05"
        ixy="-1.143E-08"
        ixz="6.1428E-07"
        iyy="7.2703E-05"
        iyz="2.0053E-08"
        izz="0.00012069" />
    </inertial>
    <visual>
      <origin
        xyz="0 0 0"
        rpy="0 0 0" />
      <geometry>
        <mesh
          filename="package://jebediah/meshes/Coxa_3.STL" />
      </geometry>
      <material
        name="">
        <color
          rgba="0.75294 0.75294 0.75294 1" />
      </material>
    </visual>
    <collision>
      <origin
        xyz="0 0 0"
        rpy="0 0 0" />
      <geometry>
        <mesh
          filename="package://jebediah/meshes/Coxa_3.STL" />
      </geometry>
    </collision>
  </link>
  <joint
    name="Servo_Coxa_3"
    type="revolute">
    <origin
      xyz="-0.085578 0.080483 -0.0051626"
      rpy="-7.4792E-15 7.4127E-15 2.357" />
    <parent
      link="base_link" />
    <child
      link="Coxa_3" />
    <axis
      xyz="0 0 1" />
    <limit
      lower="-1.5708"
      upper="1.5708"
      effort="0.9"
      velocity="5" />
  </joint>
  <link
    name="Femur">
    <inertial>
      <origin
        xyz="-1.1434E-08 8.283E-08 3.0068E-08"
        rpy="0 0 0" />
      <mass
        value="0.15818" />
      <inertia
        ixx="8.7287E-05"
        ixy="1.3518E-10"
        ixz="-6.3286E-12"
        iyy="0.00025193"
        iyz="-3.8498E-08"
        izz="0.00032491" />
    </inertial>
    <visual>
      <origin
        xyz="0 0 0"
        rpy="0 0 0" />
      <geometry>
        <mesh
          filename="package://jebediah/meshes/Femur.STL" />
      </geometry>
      <material
        name="">
        <color
          rgba="0.75294 0.75294 0.75294 1" />
      </material>
    </visual>
    <collision>
      <origin
        xyz="0 0 0"
        rpy="0 0 0" />
      <geometry>
        <mesh
          filename="package://jebediah/meshes/Femur.STL" />
      </geometry>
    </collision>
  </link>
  <joint
    name="Servo_Femur_3_1"
    type="revolute">
    <origin
      xyz="0.10132 -0.0015074 -0.00036453"
      rpy="-1.3192E-16 -2.7756E-17 -3.3307E-16" />
    <parent
      link="Coxa_3" />
    <child
      link="Femur" />
    <axis
      xyz="0 1 0" />
    <limit
      lower="-1.5708"
      upper="1.5708"
      effort="0.9"
      velocity="5" />
  </joint>
  <link
    name="Tibia_3">
    <inertial>
      <origin
        xyz="-7.3161E-08 -7.8358E-08 5.1199E-07"
        rpy="0 0 0" />
      <mass
        value="0.17087" />
      <inertia
        ixx="0.00058938"
        ixy="3.6838E-09"
        ixz="-6.3001E-05"
        iyy="0.00054103"
        iyz="-9.2364E-09"
        izz="8.2462E-05" />
    </inertial>
    <visual>
      <origin
        xyz="0 0 0"
        rpy="0 0 0" />
      <geometry>
        <mesh
          filename="package://jebediah/meshes/Tibia_3.STL" />
      </geometry>
      <material
        name="">
        <color
          rgba="0.10196 0.10196 0.10196 1" />
      </material>
    </visual>
    <collision>
      <origin
        xyz="0 0 0"
        rpy="0 0 0" />
      <geometry>
        <mesh
          filename="package://jebediah/meshes/Tibia_3.STL" />
      </geometry>
    </collision>
  </link>
  <joint
    name="Servo_Femur_3_2"
    type="revolute">
    <origin
      xyz="0.069261 0.0014932 -0.04833"
      rpy="8.3049E-16 2.7756E-17 5.6419E-29" />
    <parent
      link="Femur" />
    <child
      link="Tibia_3" />
    <axis
      xyz="0 1 0" />
    <limit
      lower="-1.5708"
      upper="1.5708"
      effort="0.9"
      velocity="5" />
  </joint>
  <link
    name="Coxa_4">
    <inertial>
      <origin
        xyz="-3.3284E-08 1.3031E-08 -7.6025E-10"
        rpy="0 0 0" />
      <mass
        value="0.1241" />
      <inertia
        ixx="8.1827E-05"
        ixy="-1.1432E-08"
        ixz="6.1428E-07"
        iyy="7.2703E-05"
        iyz="2.0053E-08"
        izz="0.00012069" />
    </inertial>
    <visual>
      <origin
        xyz="0 0 0"
        rpy="0 0 0" />
      <geometry>
        <mesh
          filename="package://jebediah/meshes/Coxa_4.STL" />
      </geometry>
      <material
        name="">
        <color
          rgba="0.75294 0.75294 0.75294 1" />
      </material>
    </visual>
    <collision>
      <origin
        xyz="0 0 0"
        rpy="0 0 0" />
      <geometry>
        <mesh
          filename="package://jebediah/meshes/Coxa_4.STL" />
      </geometry>
    </collision>
  </link>
  <joint
    name="Serv_Coxa_4"
    type="revolute">
    <origin
      xyz="-0.085591 -0.080462 -0.0051626"
      rpy="7.3339E-15 7.4004E-15 -2.3554" />
    <parent
      link="base_link" />
    <child
      link="Coxa_4" />
    <axis
      xyz="0 0 1" />
    <limit
      lower="-1.5708"
      upper="1.5708"
      effort="0.9"
      velocity="5" />
  </joint>
  <link
    name="Femur_4">
    <inertial>
      <origin
        xyz="-1.1434E-08 8.2829E-08 3.0068E-08"
        rpy="0 0 0" />
      <mass
        value="0.15818" />
      <inertia
        ixx="8.7287E-05"
        ixy="1.3518E-10"
        ixz="-6.329E-12"
        iyy="0.00025193"
        iyz="-3.8498E-08"
        izz="0.00032491" />
    </inertial>
    <visual>
      <origin
        xyz="0 0 0"
        rpy="0 0 0" />
      <geometry>
        <mesh
          filename="package://jebediah/meshes/Femur_4.STL" />
      </geometry>
      <material
        name="">
        <color
          rgba="0.75294 0.75294 0.75294 1" />
      </material>
    </visual>
    <collision>
      <origin
        xyz="0 0 0"
        rpy="0 0 0" />
      <geometry>
        <mesh
          filename="package://jebediah/meshes/Femur_4.STL" />
      </geometry>
    </collision>
  </link>
  <joint
    name="Servo_Femur_4_1"
    type="revolute">
    <origin
      xyz="0.10132 -0.0015074 -0.00036453"
      rpy="-1.3192E-16 -2.7756E-17 -2.7756E-16" />
    <parent
      link="Coxa_4" />
    <child
      link="Femur_4" />
    <axis
      xyz="0 1 0" />
    <limit
      lower="-1.5708"
      upper="1.5708"
      effort="0.9"
      velocity="5" />
  </joint>
  <link
    name="Tibia_4">
    <inertial>
      <origin
        xyz="-7.3457E-08 -7.9166E-08 5.1193E-07"
        rpy="0 0 0" />
      <mass
        value="0.17087" />
      <inertia
        ixx="0.00058938"
        ixy="3.6775E-09"
        ixz="-6.3001E-05"
        iyy="0.00054103"
        iyz="-9.2362E-09"
        izz="8.2462E-05" />
    </inertial>
    <visual>
      <origin
        xyz="0 0 0"
        rpy="0 0 0" />
      <geometry>
        <mesh
          filename="package://jebediah/meshes/Tibia_4.STL" />
      </geometry>
      <material
        name="">
        <color
          rgba="0.10196 0.10196 0.10196 1" />
      </material>
    </visual>
    <collision>
      <origin
        xyz="0 0 0"
        rpy="0 0 0" />
      <geometry>
        <mesh
          filename="package://jebediah/meshes/Tibia_4.STL" />
      </geometry>
    </collision>
  </link>
  <joint
    name="Servo_Femur_4_2"
    type="revolute">
    <origin
      xyz="0.069261 0.0014932 -0.04833"
      rpy="8.3049E-16 2.7756E-17 -5.3297E-29" />
    <parent
      link="Femur_4" />
    <child
      link="Tibia_4" />
    <axis
      xyz="0 1 0" />
    <limit
      lower="-1.5708"
      upper="1.5708"
      effort="0.9"
      velocity="5" />
  </joint>
</robot>